<?xml version="1.0" ?>
<!-- =================================================================================== -->
<!-- |    This document was autogenerated by xacro from src/relaxed_ik/src/RelaxedIK/urdfs/iona_right_arm.xacro | -->
<!-- |    EDITING THIS FILE BY HAND IS NOT RECOMMENDED                                 | -->
<!-- =================================================================================== -->
<robot name="iona_right_arm">
  <!-- Links: -->
  <link name="world"/>
  <link name="chest_link"/>
  <link name="chest_link_fixed"/>
  <joint name="chest_joint" type="prismatic">
    <parent link="world"/>
    <child link="chest_link"/>
    <axis xyz="0 0 1"/>
    <limit effort="1000.0" lower="0.0" upper="0.44" velocity="0.1"/>
    <origin rpy="0 0 3.14" xyz="0 0 0.5775"/>
    <!-- <origin xyz="0 0 0" rpy="0 0 0"/> -->
  </joint>
  <joint name="chest_joint_fixed" type="fixed">
    <parent link="chest_link"/>
    <child link="chest_link_fixed"/>
    <origin rpy="0 0 0" xyz="0 0 0"/>
  </joint>
  <!-- Right Arm: -->
  <joint name="chest_to_right_base" type="fixed">
    <parent link="chest_link_fixed"/>
    <child link="right/base_link"/>
    <origin rpy="0.0 0.7829999999999999 -1.5659999999999998" xyz="0.0 -0.142 -0.038"/>
  </joint>
  <!-- Run the macros -->
  <link name="right/base_link">
    <inertial>
      <origin rpy="0 0 0" xyz="-0.000648 -0.000166 0.084487"/>
      <mass value="1.697"/>
      <inertia ixx="0.004622" ixy="9E-06" ixz="6E-05" iyy="0.004495" iyz="9E-06" izz="0.002079"/>
    </inertial>
    <visual>
      <origin rpy="0 0 0" xyz="0 0 0"/>
      <geometry>
        <mesh filename="package://kortex_description/arms/gen3/7dof/meshes/base_link.STL"/>
      </geometry>
      <material name="">
        <color rgba="0.75294 0.75294 0.75294 1"/>
      </material>
    </visual>
    <collision>
      <origin rpy="0 0 0" xyz="0 0 0"/>
      <geometry>
        <mesh filename="package://kortex_description/arms/gen3/7dof/meshes/base_link.STL"/>
      </geometry>
    </collision>
  </link>
  <link name="right/shoulder_link">
    <inertial>
      <origin rpy="0 0 0" xyz="-2.3E-05 -0.010364 -0.07336"/>
      <mass value="1.3773"/>
      <inertia ixx="0.00457" ixy="1E-06" ixz="2E-06" iyy="0.004831" iyz="0.000448" izz="0.001409"/>
    </inertial>
    <visual>
      <origin rpy="0 0 0" xyz="0 0 0"/>
      <geometry>
        <mesh filename="package://kortex_description/arms/gen3/7dof/meshes/shoulder_link.STL"/>
      </geometry>
      <material name="">
        <color rgba="0.75294 0.75294 0.75294 1"/>
      </material>
    </visual>
    <collision>
      <origin rpy="0 0 0" xyz="0 0 0"/>
      <geometry>
        <mesh filename="package://kortex_description/arms/gen3/7dof/meshes/shoulder_link.STL"/>
      </geometry>
    </collision>
  </link>
  <joint name="right/joint_1" type="continuous">
    <origin rpy="3.1416 2.7629E-18 -4.9305E-36" xyz="0 0 0.15643"/>
    <parent link="right/base_link"/>
    <child link="right/shoulder_link"/>
    <axis xyz="0 0 1"/>
    <limit effort="39" lower="-6.28" upper="6.28" velocity="1.3963"/>
  </joint>
  <link name="right/half_arm_1_link">
    <inertial>
      <origin rpy="0 0 0" xyz="-4.4E-05 -0.09958 -0.013278"/>
      <mass value="1.1636"/>
      <inertia ixx="0.011088" ixy="5E-06" ixz="0" iyy="0.001072" iyz="-0.000691" izz="0.011255"/>
    </inertial>
    <visual>
      <origin rpy="0 0 0" xyz="0 0 0"/>
      <geometry>
        <mesh filename="package://kortex_description/arms/gen3/7dof/meshes/half_arm_1_link.STL"/>
      </geometry>
      <material name="">
        <color rgba="0.75294 0.75294 0.75294 1"/>
      </material>
    </visual>
    <collision>
      <origin rpy="0 0 0" xyz="0 0 0"/>
      <geometry>
        <mesh filename="package://kortex_description/arms/gen3/7dof/meshes/half_arm_1_link.STL"/>
      </geometry>
    </collision>
  </link>
  <joint name="right/joint_2" type="revolute">
    <origin rpy="1.5708 2.1343E-17 -1.1102E-16" xyz="0 0.005375 -0.12838"/>
    <parent link="right/shoulder_link"/>
    <child link="right/half_arm_1_link"/>
    <axis xyz="0 0 1"/>
    <limit effort="39" lower="-2.24" upper="2.24" velocity="1.3963"/>
  </joint>
  <link name="right/half_arm_2_link">
    <inertial>
      <origin rpy="0 0 0" xyz="-4.4E-05 -0.006641 -0.117892"/>
      <mass value="1.1636"/>
      <inertia ixx="0.010932" ixy="0" ixz="-7E-06" iyy="0.011127" iyz="0.000606" izz="0.001043"/>
    </inertial>
    <visual>
      <origin rpy="0 0 0" xyz="0 0 0"/>
      <geometry>
        <mesh filename="package://kortex_description/arms/gen3/7dof/meshes/half_arm_2_link.STL"/>
      </geometry>
      <material name="">
        <color rgba="0.75294 0.75294 0.75294 1"/>
      </material>
    </visual>
    <collision>
      <origin rpy="0 0 0" xyz="0 0 0"/>
      <geometry>
        <mesh filename="package://kortex_description/arms/gen3/7dof/meshes/half_arm_2_link.STL"/>
      </geometry>
    </collision>
  </link>
  <joint name="right/joint_3" type="continuous">
    <origin rpy="-1.5708 1.2326E-32 -2.9122E-16" xyz="0 -0.21038 -0.006375"/>
    <parent link="right/half_arm_1_link"/>
    <child link="right/half_arm_2_link"/>
    <axis xyz="0 0 1"/>
    <limit effort="39" lower="-6.28" upper="6.28" velocity="1.3963"/>
  </joint>
  <link name="right/forearm_link">
    <inertial>
      <origin rpy="0 0 0" xyz="-1.8E-05 -0.075478 -0.015006"/>
      <mass value="0.9302"/>
      <inertia ixx="0.008147" ixy="-1E-06" ixz="0" iyy="0.000631" iyz="-0.0005" izz="0.008316"/>
    </inertial>
    <visual>
      <origin rpy="0 0 0" xyz="0 0 0"/>
      <geometry>
        <mesh filename="package://kortex_description/arms/gen3/7dof/meshes/forearm_link.STL"/>
      </geometry>
      <material name="">
        <color rgba="0.75294 0.75294 0.75294 1"/>
      </material>
    </visual>
    <collision>
      <origin rpy="0 0 0" xyz="0 0 0"/>
      <geometry>
        <mesh filename="package://kortex_description/arms/gen3/7dof/meshes/forearm_link.STL"/>
      </geometry>
    </collision>
  </link>
  <joint name="right/joint_4" type="revolute">
    <origin rpy="1.5708 -6.6954E-17 -1.6653E-16" xyz="0 0.006375 -0.21038"/>
    <parent link="right/half_arm_2_link"/>
    <child link="right/forearm_link"/>
    <axis xyz="0 0 1"/>
    <limit effort="39" lower="-2.57" upper="2.57" velocity="1.3963"/>
  </joint>
  <link name="right/spherical_wrist_1_link">
    <inertial>
      <origin rpy="0 0 0" xyz="1E-06 -0.009432 -0.063883"/>
      <mass value="0.6781"/>
      <inertia ixx="0.001596" ixy="0" ixz="0" iyy="0.001607" iyz="0.000256" izz="0.000399"/>
    </inertial>
    <visual>
      <origin rpy="0 0 0" xyz="0 0 0"/>
      <geometry>
        <mesh filename="package://kortex_description/arms/gen3/7dof/meshes/spherical_wrist_1_link.STL"/>
      </geometry>
      <material name="">
        <color rgba="0.75294 0.75294 0.75294 1"/>
      </material>
    </visual>
    <collision>
      <origin rpy="0 0 0" xyz="0 0 0"/>
      <geometry>
        <mesh filename="package://kortex_description/arms/gen3/7dof/meshes/spherical_wrist_1_link.STL"/>
      </geometry>
    </collision>
  </link>
  <joint name="right/joint_5" type="continuous">
    <origin rpy="-1.5708 2.2204E-16 -6.373E-17" xyz="0 -0.20843 -0.006375"/>
    <parent link="right/forearm_link"/>
    <child link="right/spherical_wrist_1_link"/>
    <axis xyz="0 0 1"/>
    <limit effort="9" lower="-6.28" upper="6.28" velocity="1.2218"/>
  </joint>
  <link name="right/spherical_wrist_2_link">
    <inertial>
      <origin rpy="0 0 0" xyz="1E-06 -0.045483 -0.00965"/>
      <mass value="0.6781"/>
      <inertia ixx="0.001641" ixy="0" ixz="0" iyy="0.00041" iyz="-0.000278" izz="0.001641"/>
    </inertial>
    <visual>
      <origin rpy="0 0 0" xyz="0 0 0"/>
      <geometry>
        <mesh filename="package://kortex_description/arms/gen3/7dof/meshes/spherical_wrist_2_link.STL"/>
      </geometry>
      <material name="">
        <color rgba="0.75294 0.75294 0.75294 1"/>
      </material>
    </visual>
    <collision>
      <origin rpy="0 0 0" xyz="0 0 0"/>
      <geometry>
        <mesh filename="package://kortex_description/arms/gen3/7dof/meshes/spherical_wrist_2_link.STL"/>
      </geometry>
    </collision>
  </link>
  <joint name="right/joint_6" type="revolute">
    <origin rpy="1.5708 9.2076E-28 -8.2157E-15" xyz="0 0.00017505 -0.10593"/>
    <parent link="right/spherical_wrist_1_link"/>
    <child link="right/spherical_wrist_2_link"/>
    <axis xyz="0 0 1"/>
    <limit effort="9" lower="-2.09" upper="2.09" velocity="1.2218"/>
  </joint>
  <link name="right/bracelet_link">
    <inertial>
      <origin rpy="0 0 0" xyz="-9.3E-05 0.000132 -0.022905"/>
      <mass value="0.364"/>
      <inertia ixx="0.000214" ixy="0" ixz="1E-06" iyy="0.000223" iyz="-2E-06" izz="0.00024"/>
    </inertial>
    <visual>
      <origin rpy="0 0 0" xyz="0 0 0"/>
      <geometry>
        <mesh filename="package://kortex_description/arms/gen3/7dof/meshes/bracelet_no_vision_link.STL"/>
      </geometry>
      <material name="">
        <color rgba="0.75294 0.75294 0.75294 1"/>
      </material>
    </visual>
    <collision>
      <origin rpy="0 0 0" xyz="0 0 0"/>
      <geometry>
        <mesh filename="package://kortex_description/arms/gen3/7dof/meshes/bracelet_no_vision_link.STL"/>
      </geometry>
    </collision>
  </link>
  <joint name="right/joint_7" type="continuous">
    <origin rpy="-1.5708 -5.5511E-17 9.6396E-17" xyz="0 -0.10593 -0.00017505"/>
    <parent link="right/spherical_wrist_2_link"/>
    <child link="right/bracelet_link"/>
    <axis xyz="0 0 1"/>
    <limit effort="9" lower="-6.28" upper="6.28" velocity="1.2218"/>
  </joint>
  <link name="right/end_effector_link"/>
  <joint name="right/end_effector" type="fixed">
    <origin rpy="3.14159265358979 1.09937075168372E-32 0" xyz="0 0 -0.0615250000000001"/>
    <parent link="right/bracelet_link"/>
    <child link="right/end_effector_link"/>
    <axis xyz="0 0 0"/>
  </joint>
  <!-- This line was removed by Kinova because we replaced the transmission file with our own 
    <xacro:include filename="$(find robotiq_2f_85_gripper_visualization)/urdf/robotiq_arg2f_transmission.xacro" /> -->
  <!-- Tool frame used by the arm -->
  <link name="right/tool_frame"/>
  <joint name="right/tool_frame_joint" type="fixed">
    <origin rpy="0 0 0" xyz="0 0 0.120"/>
    <parent link="right/end_effector_link"/>
    <child link="right/tool_frame"/>
    <axis xyz="0 0 0"/>
  </joint>
  <!-- This joint was added by Kinova -->
  <joint name="right/gripper_base_joint" type="fixed">
    <parent link="right/end_effector_link"/>
    <child link="right/robotiq_arg2f_base_link"/>
    <origin rpy="0.0 0.0 1.57" xyz="0.0 0.0 0.0"/>
  </joint>
  <link name="right/robotiq_arg2f_base_link">
    <inertial>
      <origin rpy="0 0 0" xyz="8.625E-08 -4.6583E-06 0.03145"/>
      <mass value="0.22652"/>
      <inertia ixx="0.00020005" ixy="-4.2442E-10" ixz="-2.9069E-10" iyy="0.00017832" iyz="-3.4402E-08" izz="0.00013478"/>
    </inertial>
    <visual>
      <origin rpy="0 0 0" xyz="0 0 0"/>
      <geometry>
        <!-- The DAE file doesn't show well in Gazebo so we're using the STL instead -->
        <!-- <mesh filename="package://kortex_description/grippers/robotiq_2f_85/meshes/visual/robotiq_arg2f_85_base_link.dae" scale="0.001 0.001 0.001"/> -->
        <mesh filename="package://kortex_description/grippers/robotiq_2f_85/meshes/collision/robotiq_arg2f_base_link.stl"/>
      </geometry>
      <material name="">
        <color rgba="0.1 0.1 0.1 1"/>
      </material>
    </visual>
    <collision>
      <origin rpy="0 0 0" xyz="0 0 0"/>
      <geometry>
        <mesh filename="package://kortex_description/grippers/robotiq_2f_85/meshes/collision/robotiq_arg2f_base_link.stl"/>
      </geometry>
    </collision>
  </link>
  <gazebo reference="right/robotiq_arg2f_base_link">
    <material>Gazebo/Black</material>
  </gazebo>
  <link name="right/left_outer_knuckle">
    <inertial>
      <origin rpy="0 0 0" xyz="-0.000200000000003065 0.0199435877845359 0.0292245259211331"/>
      <mass value="0.00853198276973456"/>
      <inertia ixx="2.89328108496468E-06" ixy="-1.57935047237397E-19" ixz="-1.93980378593255E-19" iyy="1.86719750325683E-06" iyz="-1.21858577871576E-06" izz="1.21905238907251E-06"/>
    </inertial>
    <visual>
      <origin rpy="0 0 0" xyz="0 0 0"/>
      <geometry>
        <mesh filename="package://kortex_description/grippers/robotiq_2f_85/meshes/visual/robotiq_arg2f_85_outer_knuckle.dae" scale="0.001 0.001 0.001"/>
      </geometry>
      <material name="">
        <color rgba="0.792156862745098 0.819607843137255 0.933333333333333 1"/>
      </material>
    </visual>
    <collision>
      <origin rpy="0 0 0" xyz="0 0 0"/>
      <geometry>
        <mesh filename="package://kortex_description/grippers/robotiq_2f_85/meshes/collision/robotiq_arg2f_85_outer_knuckle.dae" scale="0.001 0.001 0.001"/>
      </geometry>
    </collision>
  </link>
  <link name="right/left_outer_finger">
    <inertial>
      <origin rpy="0 0 0" xyz="0.00030115855001899 0.0373907951953854 -0.0208027427000385"/>
      <mass value="0.022614240507152"/>
      <inertia ixx="1.52518312458174E-05" ixy="9.76583423954399E-10" ixz="-5.43838577022588E-10" iyy="6.17694243867776E-06" iyz="6.78636130740228E-06" izz="1.16494917907219E-05"/>
    </inertial>
    <visual>
      <origin rpy="0 0 0" xyz="0 0 0"/>
      <geometry>
        <mesh filename="package://kortex_description/grippers/robotiq_2f_85/meshes/visual/robotiq_arg2f_85_outer_finger.dae" scale="0.001 0.001 0.001"/>
      </geometry>
      <material name="">
        <color rgba="0.1 0.1 0.1 1"/>
      </material>
    </visual>
    <collision>
      <origin rpy="0 0 0" xyz="0 0 0"/>
      <geometry>
        <mesh filename="package://kortex_description/grippers/robotiq_2f_85/meshes/collision/robotiq_arg2f_85_outer_finger.dae" scale="0.001 0.001 0.001"/>
      </geometry>
    </collision>
  </link>
  <link name="right/left_inner_finger">
    <inertial>
      <origin rpy="0 0 0" xyz="0.000299999999999317 0.0160078233491243 -0.0136945669206257"/>
      <mass value="0.0104003125914103"/>
      <inertia ixx="2.71909453810972E-06" ixy="1.35402465472579E-21" ixz="-7.1817349065269E-22" iyy="7.69100314106116E-07" iyz="6.74715432769696E-07" izz="2.30315190420171E-06"/>
    </inertial>
    <visual>
      <origin rpy="0 0 0" xyz="0 0 0"/>
      <geometry>
        <mesh filename="package://kortex_description/grippers/robotiq_2f_85/meshes/visual/robotiq_arg2f_85_inner_finger.dae" scale="0.001 0.001 0.001"/>
      </geometry>
      <material name="">
        <color rgba="0.1 0.1 0.1 1"/>
      </material>
    </visual>
    <collision>
      <origin rpy="0 0 0" xyz="0 0 0"/>
      <geometry>
        <mesh filename="package://kortex_description/grippers/robotiq_2f_85/meshes/collision/robotiq_arg2f_85_inner_finger.dae" scale="0.001 0.001 0.001"/>
      </geometry>
    </collision>
  </link>
  <link name="right/left_inner_finger_pad">
    <visual>
      <origin rpy="0 0 0" xyz="0 0 0"/>
      <geometry>
        <box size="0.022 0.00635 0.0375"/>
      </geometry>
      <material name="">
        <color rgba="0.9 0.9 0.9 1"/>
      </material>
    </visual>
    <collision>
      <origin rpy="0 0 0" xyz="0 0 0"/>
      <geometry>
        <box size="0.022 0.00635 0.0375"/>
      </geometry>
      <material name="">
        <color rgba="0.9 0.0 0.0 1"/>
      </material>
    </collision>
  </link>
  <link name="right/left_inner_knuckle">
    <inertial>
      <origin rpy="0 0 0" xyz="0.000123011831763771 0.0507850843201817 0.00103968640075166"/>
      <mass value="0.0271177346495152"/>
      <inertia ixx="2.61910379223783E-05" ixy="-2.43616858946494E-07" ixz="-6.37789906117123E-09" iyy="2.8270243746167E-06" iyz="-5.37200748039765E-07" izz="2.83695868220296E-05"/>
    </inertial>
    <visual>
      <origin rpy="0 0 0" xyz="0 0 0"/>
      <geometry>
        <mesh filename="package://kortex_description/grippers/robotiq_2f_85/meshes/visual/robotiq_arg2f_85_inner_knuckle.dae" scale="0.001 0.001 0.001"/>
      </geometry>
      <material name="">
        <color rgba="0.1 0.1 0.1 1"/>
      </material>
    </visual>
    <collision>
      <origin rpy="0 0 0" xyz="0 0 0"/>
      <geometry>
        <mesh filename="package://kortex_description/grippers/robotiq_2f_85/meshes/collision/robotiq_arg2f_85_inner_knuckle.dae" scale="0.001 0.001 0.001"/>
      </geometry>
    </collision>
  </link>
  <link name="right/right_outer_knuckle">
    <inertial>
      <origin rpy="0 0 0" xyz="-0.000200000000003065 0.0199435877845359 0.0292245259211331"/>
      <mass value="0.00853198276973456"/>
      <inertia ixx="2.89328108496468E-06" ixy="-1.57935047237397E-19" ixz="-1.93980378593255E-19" iyy="1.86719750325683E-06" iyz="-1.21858577871576E-06" izz="1.21905238907251E-06"/>
    </inertial>
    <visual>
      <origin rpy="0 0 0" xyz="0 0 0"/>
      <geometry>
        <mesh filename="package://kortex_description/grippers/robotiq_2f_85/meshes/visual/robotiq_arg2f_85_outer_knuckle.dae" scale="0.001 0.001 0.001"/>
      </geometry>
      <material name="">
        <color rgba="0.792156862745098 0.819607843137255 0.933333333333333 1"/>
      </material>
    </visual>
    <collision>
      <origin rpy="0 0 0" xyz="0 0 0"/>
      <geometry>
        <mesh filename="package://kortex_description/grippers/robotiq_2f_85/meshes/collision/robotiq_arg2f_85_outer_knuckle.dae" scale="0.001 0.001 0.001"/>
      </geometry>
    </collision>
  </link>
  <link name="right/right_outer_finger">
    <inertial>
      <origin rpy="0 0 0" xyz="0.00030115855001899 0.0373907951953854 -0.0208027427000385"/>
      <mass value="0.022614240507152"/>
      <inertia ixx="1.52518312458174E-05" ixy="9.76583423954399E-10" ixz="-5.43838577022588E-10" iyy="6.17694243867776E-06" iyz="6.78636130740228E-06" izz="1.16494917907219E-05"/>
    </inertial>
    <visual>
      <origin rpy="0 0 0" xyz="0 0 0"/>
      <geometry>
        <mesh filename="package://kortex_description/grippers/robotiq_2f_85/meshes/visual/robotiq_arg2f_85_outer_finger.dae" scale="0.001 0.001 0.001"/>
      </geometry>
      <material name="">
        <color rgba="0.1 0.1 0.1 1"/>
      </material>
    </visual>
    <collision>
      <origin rpy="0 0 0" xyz="0 0 0"/>
      <geometry>
        <mesh filename="package://kortex_description/grippers/robotiq_2f_85/meshes/collision/robotiq_arg2f_85_outer_finger.dae" scale="0.001 0.001 0.001"/>
      </geometry>
    </collision>
  </link>
  <link name="right/right_inner_finger">
    <inertial>
      <origin rpy="0 0 0" xyz="0.000299999999999317 0.0160078233491243 -0.0136945669206257"/>
      <mass value="0.0104003125914103"/>
      <inertia ixx="2.71909453810972E-06" ixy="1.35402465472579E-21" ixz="-7.1817349065269E-22" iyy="7.69100314106116E-07" iyz="6.74715432769696E-07" izz="2.30315190420171E-06"/>
    </inertial>
    <visual>
      <origin rpy="0 0 0" xyz="0 0 0"/>
      <geometry>
        <mesh filename="package://kortex_description/grippers/robotiq_2f_85/meshes/visual/robotiq_arg2f_85_inner_finger.dae" scale="0.001 0.001 0.001"/>
      </geometry>
      <material name="">
        <color rgba="0.1 0.1 0.1 1"/>
      </material>
    </visual>
    <collision>
      <origin rpy="0 0 0" xyz="0 0 0"/>
      <geometry>
        <mesh filename="package://kortex_description/grippers/robotiq_2f_85/meshes/collision/robotiq_arg2f_85_inner_finger.dae" scale="0.001 0.001 0.001"/>
      </geometry>
    </collision>
  </link>
  <link name="right/right_inner_finger_pad">
    <visual>
      <origin rpy="0 0 0" xyz="0 0 0"/>
      <geometry>
        <box size="0.022 0.00635 0.0375"/>
      </geometry>
      <material name="">
        <color rgba="0.9 0.9 0.9 1"/>
      </material>
    </visual>
    <collision>
      <origin rpy="0 0 0" xyz="0 0 0"/>
      <geometry>
        <box size="0.022 0.00635 0.0375"/>
      </geometry>
      <material name="">
        <color rgba="0.9 0.0 0.0 1"/>
      </material>
    </collision>
  </link>
  <link name="right/right_inner_knuckle">
    <inertial>
      <origin rpy="0 0 0" xyz="0.000123011831763771 0.0507850843201817 0.00103968640075166"/>
      <mass value="0.0271177346495152"/>
      <inertia ixx="2.61910379223783E-05" ixy="-2.43616858946494E-07" ixz="-6.37789906117123E-09" iyy="2.8270243746167E-06" iyz="-5.37200748039765E-07" izz="2.83695868220296E-05"/>
    </inertial>
    <visual>
      <origin rpy="0 0 0" xyz="0 0 0"/>
      <geometry>
        <mesh filename="package://kortex_description/grippers/robotiq_2f_85/meshes/visual/robotiq_arg2f_85_inner_knuckle.dae" scale="0.001 0.001 0.001"/>
      </geometry>
      <material name="">
        <color rgba="0.1 0.1 0.1 1"/>
      </material>
    </visual>
    <collision>
      <origin rpy="0 0 0" xyz="0 0 0"/>
      <geometry>
        <mesh filename="package://kortex_description/grippers/robotiq_2f_85/meshes/collision/robotiq_arg2f_85_inner_knuckle.dae" scale="0.001 0.001 0.001"/>
      </geometry>
    </collision>
  </link>
  <joint name="right/finger_joint" type="revolute">
    <origin rpy="0 0 3.141592653589793" xyz="0 -0.0306011 0.054904"/>
    <parent link="right/robotiq_arg2f_base_link"/>
    <child link="right/left_outer_knuckle"/>
    <axis xyz="1 0 0"/>
    <limit effort="1000" lower="0" upper="0.8" velocity="2.0"/>
  </joint>
  <joint name="right/left_outer_finger_joint" type="fixed">
    <origin rpy="0 0 0" xyz="0 0.0315 -0.0041"/>
    <parent link="right/left_outer_knuckle"/>
    <child link="right/left_outer_finger"/>
    <axis xyz="1 0 0"/>
  </joint>
  <joint name="right/left_inner_knuckle_joint" type="revolute">
    <!-- <origin xyz="0 ${reflect * -0.0127} 0.06142" rpy="${pi / 2 + .725} 0 ${(reflect - 1) * pi / 2}" /> -->
    <origin rpy="0 0 3.141592653589793" xyz="0 -0.0127 0.06142"/>
    <parent link="right/robotiq_arg2f_base_link"/>
    <child link="right/left_inner_knuckle"/>
    <axis xyz="1 0 0"/>
    <limit effort="1000" lower="0" upper="0.8757" velocity="2.0"/>
    <mimic joint="right/finger_joint" multiplier="1" offset="0"/>
  </joint>
  <joint name="right/left_inner_finger_joint" type="revolute">
    <origin rpy="0 0 0" xyz="0 0.0061 0.0471"/>
    <parent link="right/left_outer_finger"/>
    <child link="right/left_inner_finger"/>
    <axis xyz="1 0 0"/>
    <limit effort="1000" lower="-0.8757" upper="0.8757" velocity="2.0"/>
    <mimic joint="right/finger_joint" multiplier="-1" offset="0"/>
  </joint>
  <joint name="right/left_inner_finger_pad_joint" type="fixed">
    <origin rpy="0 0 0" xyz="0 -0.0220203446692936 0.03242"/>
    <parent link="right/left_inner_finger"/>
    <child link="right/left_inner_finger_pad"/>
    <axis xyz="0 0 1"/>
  </joint>
  <joint name="right/right_outer_knuckle_joint" type="revolute">
    <origin rpy="0 0 0" xyz="0 0.0306011 0.054904"/>
    <parent link="right/robotiq_arg2f_base_link"/>
    <child link="right/right_outer_knuckle"/>
    <axis xyz="1 0 0"/>
    <limit effort="1000" lower="0" upper="0.81" velocity="2.0"/>
    <mimic joint="right/finger_joint" multiplier="1" offset="0"/>
  </joint>
  <joint name="right/right_outer_finger_joint" type="fixed">
    <origin rpy="0 0 0" xyz="0 0.0315 -0.0041"/>
    <parent link="right/right_outer_knuckle"/>
    <child link="right/right_outer_finger"/>
    <axis xyz="1 0 0"/>
  </joint>
  <joint name="right/right_inner_knuckle_joint" type="revolute">
    <!-- <origin xyz="0 ${reflect * -0.0127} 0.06142" rpy="${pi / 2 + .725} 0 ${(reflect - 1) * pi / 2}" /> -->
    <origin rpy="0 0 0.0" xyz="0 0.0127 0.06142"/>
    <parent link="right/robotiq_arg2f_base_link"/>
    <child link="right/right_inner_knuckle"/>
    <axis xyz="1 0 0"/>
    <limit effort="1000" lower="0" upper="0.8757" velocity="2.0"/>
    <mimic joint="right/finger_joint" multiplier="1" offset="0"/>
  </joint>
  <joint name="right/right_inner_finger_joint" type="revolute">
    <origin rpy="0 0 0" xyz="0 0.0061 0.0471"/>
    <parent link="right/right_outer_finger"/>
    <child link="right/right_inner_finger"/>
    <axis xyz="1 0 0"/>
    <limit effort="1000" lower="-0.8757" upper="0.8757" velocity="2.0"/>
    <mimic joint="right/finger_joint" multiplier="-1" offset="0"/>
  </joint>
  <joint name="right/right_inner_finger_pad_joint" type="fixed">
    <origin rpy="0 0 0" xyz="0 -0.0220203446692936 0.03242"/>
    <parent link="right/right_inner_finger"/>
    <child link="right/right_inner_finger_pad"/>
    <axis xyz="0 0 1"/>
  </joint>
  <!-- Transmissions are loaded in the generic kortex xacro when simulation is enabled -->
  <!-- <xacro:robotiq_arg2f_transmission prefix="${prefix}"/> -->
  <!-- Left Arm: -->
  <!-- <link name="left_arm_mount"/>  

    <joint name="chest_to_left_arm_mount" type="fixed">
        <parent link="chest_link"/>
        <child link="left_arm_mount"/>
        <origin xyz="${x_offset} ${y_offset} ${z_offset}" rpy="${-0.0174 * roll_offset} ${0.0174 * pitch_offset} ${0.0174 * yaw_offset}"/>
    </joint>
    <joint name="left_arm_mount_to_arm" type="fixed">
        <parent link="left_arm_mount"/>
        <child link="left/base_link"/>
        <origin xyz="0 0 0" rpy="0 0 1.57"/>
    </joint>
    <xacro:load_robot 
        arm="gen3" 
        gripper="robotiq_2f_85" 
        dof="7"                    
        vision="false" 
        sim="false" 
        prefix="left/">
    </xacro:load_robot>   -->
</robot>

